File: physicalRobot/InstronLegStiffness/1RubberBand.is_comp_RawData/Specimen_RawData_5.csv
Time,Extension,Load
(sec),(mm),(N)
0.00000,0.00000,-0.74809
0.10000,-0.19659,-1.50541
0.20000,-0.40144,-1.65716
0.30000,-0.60197,-1.76665
0.40000,-0.80203,-1.91162
0.50000,-1.00200,-2.04079
0.60000,-1.20206,-2.14872
0.70000,-1.40203,-2.27121
0.80000,-1.60200,-2.39033
0.90000,-1.80197,-2.49818
1.00000,-2.00203,-2.61076
1.10000,-2.20191,-2.71337
1.20000,-2.40188,-2.81184
1.30000,-2.60194,-2.91475
1.40000,-2.80200,-3.02622
1.50000,-3.00197,-3.10354
1.60000,-3.20184,-3.20485
1.70000,-3.40200,-3.26927
1.80000,-3.60197,-3.36731
1.90000,-3.80213,-3.44943
2.00000,-4.00200,-3.53705
2.10000,-4.20206,-3.62239
2.20000,-4.40213,-3.71434
2.30000,-4.60209,-3.78292
2.40000,-4.80206,-3.85290
2.50000,-5.00194,-3.91359
2.60000,-5.20209,-4.00190
2.70000,-5.40197,-4.06719
2.80000,-5.60194,-4.15031
2.90000,-5.80209,-4.23187
3.00000,-6.00197,-4.28560
3.10000,-6.20203,-4.35062
3.20000,-6.40200,-4.41651
3.30000,-6.60206,-4.47775
3.40000,-6.80194,-4.54294
3.50000,-7.00200,-4.61499
3.60000,-7.20206,-4.65630
3.70000,-7.40203,-4.71314
3.80000,-7.60209,-4.78548
3.90000,-7.80197,-4.82006
4.00000,-8.00194,-4.88626
4.10000,-8.20191,-4.93981
4.20000,-8.40197,-5.00497
4.30000,-8.60194,-5.05253
4.40000,-8.80200,-5.12827
4.50000,-9.00188,-5.16812
4.60000,-9.20203,-5.22351
4.70000,-9.40200,-5.29220
4.80000,-9.60206,-5.34191
4.90000,-9.80213,-5.40231
5.00000,-10.00191,-5.46635
5.10000,-10.20197,-5.52600
5.20000,-10.40213,-5.56641
5.30000,-10.60200,-5.63396
5.40000,-10.80206,-5.68464
5.50000,-11.00203,-5.72724
5.60000,-11.20200,-5.80679
5.70000,-11.40197,-5.84453
5.80000,-11.60203,-5.88458
5.90000,-11.80200,-5.94126
6.00000,-12.00197,-5.99463
6.10000,-12.20194,-6.02333
6.20000,-12.40200,-6.06971
6.30000,-12.60197,-6.11923
6.40000,-12.80203,-6.16881
6.50000,-13.00191,-6.20852
6.60000,-13.20197,-6.25613
6.70000,-13.40194,-6.30270
6.80000,-13.60200,-6.35350
6.90000,-13.80206,-6.38288
7.00000,-14.00203,-6.45601
7.10000,-14.20219,-6.49480
7.20000,-14.40206,-6.54896
7.30000,-14.60184,-6.59672
7.40000,-14.80209,-6.64165
7.50000,-15.00197,-6.69424
7.60000,-15.20194,-6.74013
7.70000,-15.40191,-6.78812
7.80000,-15.60188,-6.83420
7.90000,-15.80213,-6.87823
8.00000,-16.00200,-6.91591
8.10000,-16.20197,-6.96048
8.20000,-16.40194,-7.00381
8.30000,-16.60200,-7.04205
8.40000,-16.80197,-7.08223
8.50000,-17.00194,-7.10765
8.60000,-17.20200,-7.16019
8.70000,-17.40188,-7.21021
8.80000,-17.60194,-7.24903
8.90000,-17.80200,-7.26890
9.00000,-18.00197,-7.30191
9.10000,-18.20184,-7.34262
9.20000,-18.40191,-7.39548
9.30000,-18.60197,-7.42538
9.40000,-18.80203,-7.47524
9.50000,-19.00200,-7.51089
9.60000,-19.20206,-7.53754
9.70000,-19.40203,-7.58605
9.80000,-19.60200,-7.60816
9.90000,-19.80206,-7.63219
10.00000,-20.00203,-7.68734
10.10000,-20.20209,-7.72884
10.20000,-20.40188,-7.78344
10.30000,-20.60194,-7.81309
10.40000,-20.80200,-7.85159
10.50000,-21.00197,-7.89025
10.60000,-21.20194,-7.93506
10.70000,-21.40200,-7.98299
10.80000,-21.60188,-8.02300
10.90000,-21.80203,-8.06723
11.00000,-22.00200,-8.11411
11.10000,-22.20178,-8.13540
11.20000,-22.40194,-8.17199
11.30000,-22.60209,-8.20391
11.40000,-22.80206,-8.23839
11.50000,-23.00194,-8.27464
11.60000,-23.20200,-8.32265
11.70000,-23.40197,-8.36563
11.80000,-23.60194,-8.41474
11.90000,-23.80200,-8.44034
12.00000,-24.00197,-8.47343
12.10000,-24.20203,-8.52073
12.20000,-24.40200,-8.57703
12.30000,-24.60197,-8.60971
12.40000,-24.80194,-8.67636
12.50000,-25.00200,-8.71928
12.60000,-25.20197,-8.75573
12.70000,-25.40203,-8.80728
12.80000,-25.60200,-8.86023
12.90000,-25.80206,-8.90285
13.00000,-26.00203,-8.94043
13.10000,-26.20200,-8.98394
13.20000,-26.40197,-9.03174
13.30000,-26.60194,-9.08308
13.40000,-26.80200,-9.14389
13.50000,-27.00197,-9.19379
13.60000,-27.20203,-9.26234
13.70000,-27.40200,-9.28766
13.80000,-27.60206,-9.33886
13.90000,-27.80213,-9.39162
14.00000,-28.00200,-9.39773
14.10000,-28.20206,-9.46200
14.20000,-28.40194,-9.51048
14.30000,-28.60200,-9.56775
14.40000,-28.80197,-9.61494
14.50000,-29.00203,-9.68302
14.60000,-29.20200,-9.74089
14.70000,-29.40206,-9.78967
14.80000,-29.60203,-9.84166
14.90000,-29.80181,-9.88559
15.00000,-30.00188,-9.93490
15.10000,-30.20194,-9.99314
15.20000,-30.40200,-10.04565
15.30000,-30.60206,-10.10515
15.40000,-30.80213,-10.15300
15.50000,-31.00200,-10.20149
15.60000,-31.20206,-10.24876
15.70000,-31.40203,-10.29961
15.80000,-31.60210,-10.36117
15.90000,-31.80197,-10.39259
16.00000,-32.00194,-10.45127
16.10000,-32.20209,-10.50050
16.20000,-32.40197,-10.53886
16.30000,-32.60175,-10.57975
16.40000,-32.80209,-10.64875
16.50000,-33.00197,-10.68956
16.60000,-33.20194,-10.74535
16.70000,-33.40200,-10.78190
16.80000,-33.60206,-10.86649
16.90000,-33.80203,-10.90385
17.00000,-34.00200,-10.96073
17.10000,-34.20197,-10.99445
17.20000,-34.40203,-11.05347
17.30000,-34.60209,-11.10213
17.40000,-34.80206,-11.15316
17.50000,-35.00203,-11.18275
17.60000,-35.20200,-11.24040
17.70000,-35.40197,-11.30955
17.80000,-35.60194,-11.36046
17.90000,-35.80191,-11.41541
18.00000,-36.00197,-11.47531
18.10000,-36.20203,-11.51336
18.20000,-36.40200,-11.56977
18.30000,-36.60197,-11.61347
18.40000,-36.80203,-11.68639
18.50000,-37.00191,-11.72927
18.60000,-37.20206,-11.79913
18.70000,-37.40213,-11.83669
18.80000,-37.60200,-11.92302
18.90000,-37.80216,-11.97079
19.00000,-38.00203,-12.03684
19.10000,-38.20200,-12.08258
19.20000,-38.40188,-12.18353
19.30000,-38.60185,-12.20676
19.40000,-38.80200,-12.27546
19.50000,-39.00197,-12.30629
19.60000,-39.20194,-12.39493
19.70000,-39.40200,-12.43379
19.80000,-39.60216,-12.51267
19.90000,-39.80203,-12.57721
20.00000,-40.00200,-12.64490
20.10000,-40.20206,-12.68164
20.20000,-40.40203,-12.74500
20.30000,-40.60200,-12.80303
20.40000,-40.80197,-12.88457
20.50000,-41.00203,-12.95157
20.60000,-41.20200,-13.00303
20.70000,-41.40188,-13.09710
20.80000,-41.60184,-13.15534
20.90000,-41.80200,-13.21179
21.00000,-42.00197,-13.25144
21.10000,-42.20194,-13.31369
21.20000,-42.40200,-13.38034
21.30000,-42.60197,-13.45633
21.40000,-42.80194,-13.51535
21.50000,-43.00200,-13.56779
21.60000,-43.20187,-13.63604
21.70000,-43.40194,-13.70331
21.80000,-43.60200,-13.80143
21.90000,-43.80188,-13.85378
22.00000,-44.00194,-13.95161
22.10000,-44.20191,-13.99949
22.20000,-44.40206,-14.10566
22.30000,-44.60194,-14.15722
22.40000,-44.80200,-14.21212
22.50000,-45.00197,-14.26490
22.60000,-45.20185,-14.35603
22.67900,-45.36000,-14.43573