File: physicalRobot/InstronLegStiffness/4RubberBands.is_comp_RawData/Specimen_RawData_1.csv
Time,Extension,Load
(sec),(mm),(N)
0.00000,0.00000,1.08122
0.10000,-0.19688,0.06261
0.20000,-0.40144,-4.19335
0.26500,-0.53194,-9.24123
0.36500,-0.73200,-13.45432
0.46500,-0.93206,-14.36859
0.56500,-1.13203,-14.99402
0.66500,-1.33209,-15.59695
0.76500,-1.53197,-16.13603
0.86500,-1.73203,-16.70684
0.96500,-1.93191,-17.23269
1.06500,-2.13188,-17.82832
1.16500,-2.33203,-18.34783
1.26500,-2.53191,-18.86053
1.36500,-2.73197,-19.33772
1.46500,-2.93194,-19.84460
1.56500,-3.13200,-20.24700
1.66500,-3.33206,-20.66620
1.76500,-3.53194,-21.12031
1.86500,-3.73181,-21.53667
1.96500,-3.93206,-21.96589
2.06500,-4.13203,-22.34581
2.16500,-4.33191,-22.72763
2.26500,-4.53188,-23.12103
2.36500,-4.73203,-23.48258
2.46500,-4.93181,-23.87278
2.56500,-5.13188,-24.16935
2.66500,-5.33203,-24.53599
2.76500,-5.53209,-24.86064
2.86500,-5.73197,-25.18853
2.96500,-5.93203,-25.54730
3.06500,-6.13219,-25.90626
3.16500,-6.33206,-26.17615
3.26500,-6.53194,-26.50197
3.36500,-6.73209,-26.83095
3.46500,-6.93206,-27.15822
3.56500,-7.13194,-27.43044
3.66500,-7.33209,-27.70935
3.76500,-7.53197,-27.99143
3.86500,-7.73194,-28.31208
3.96500,-7.93191,-28.60229
4.06500,-8.13197,-28.85603
4.16500,-8.33203,-29.14146
4.26500,-8.53191,-29.43327
4.36500,-8.73188,-29.74672
4.46500,-8.93203,-30.00847
4.56500,-9.13209,-30.26573
4.66500,-9.33206,-30.54721
4.76500,-9.53203,-30.82539
4.86500,-9.73200,-31.11240
4.96500,-9.93206,-31.32523
5.06500,-10.13203,-31.62945
5.16500,-10.33200,-31.89668
5.26500,-10.53197,-32.15573
5.36500,-10.73194,-32.39947
5.46500,-10.93191,-32.65147
5.56500,-11.13197,-32.94086
5.66500,-11.33203,-33.19251
5.76500,-11.53200,-33.45366
5.86500,-11.73197,-33.68173
5.96500,-11.93203,-33.92038
6.06500,-12.13209,-34.17303
6.16500,-12.33197,-34.44873
6.26500,-12.53194,-34.69416
6.36500,-12.73200,-34.97122
6.46500,-12.93197,-35.18702
6.56500,-13.13203,-35.41014
6.66500,-13.33191,-35.68063
6.76500,-13.53197,-35.97725
6.86500,-13.73203,-36.26251
6.96500,-13.93200,-36.50319
7.06500,-14.13206,-36.78645
7.16500,-14.33203,-37.04258
7.26500,-14.53200,-37.29547
7.36500,-14.73169,-37.55859
7.46500,-14.93213,-37.78400
7.56500,-15.13209,-38.02127
7.66500,-15.33206,-38.33741
7.76500,-15.53203,-38.60110
7.86500,-15.73209,-38.85540
7.96500,-15.93206,-39.11706
8.06500,-16.13203,-39.31012
8.16500,-16.33200,-39.54102
8.26500,-16.53188,-39.84233
8.36500,-16.73203,-40.10547
8.46500,-16.93200,-40.41615
8.56500,-17.13188,-40.61650
8.66500,-17.33194,-40.89803
8.76500,-17.53200,-41.10752
8.86500,-17.73188,-41.35391
8.96500,-17.93194,-41.58415
9.06500,-18.13200,-41.83207
9.16500,-18.33197,-42.06490
9.26500,-18.53194,-42.33522
9.36500,-18.73200,-42.55334
9.46500,-18.93206,-42.83432
9.56500,-19.13184,-43.10688
9.66500,-19.33209,-43.33429
9.76500,-19.53197,-43.54513
9.86500,-19.73203,-43.78596
9.96500,-19.93200,-44.01850
10.06500,-20.13197,-44.25365
10.16500,-20.33203,-44.55585
10.26500,-20.53191,-44.79972
10.36500,-20.73197,-45.03433
10.46500,-20.93203,-45.31821
10.56500,-21.13200,-45.57647
10.66500,-21.33197,-45.79132
10.76500,-21.53203,-46.04813
10.86500,-21.73209,-46.30977
10.96500,-21.93206,-46.60539
11.06500,-22.13203,-46.85227
11.16500,-22.33200,-47.13345
11.26500,-22.53188,-47.39813
11.36500,-22.73213,-47.65350
11.46500,-22.93200,-47.89350
11.56500,-23.13188,-48.19188
11.66500,-23.33203,-48.47676
11.76500,-23.53200,-48.74692
11.86500,-23.73197,-48.98712
11.96500,-23.93203,-49.24553
12.06500,-24.13210,-49.51416
12.16500,-24.33206,-49.84307
12.26500,-24.53194,-50.12188
12.36500,-24.73200,-50.39354
12.46500,-24.93188,-50.67277
12.56500,-25.13203,-50.92113
12.66500,-25.33200,-51.24655
12.76500,-25.53197,-51.52616
12.86500,-25.73203,-51.83330
12.96500,-25.93200,-52.15774
13.06500,-26.13197,-52.43047
13.16500,-26.33194,-52.74787
13.26500,-26.53200,-53.02209
13.36500,-26.73197,-53.32991
13.46500,-26.93203,-53.59635
13.56500,-27.13209,-53.88823
13.66500,-27.33206,-54.20774
13.76500,-27.53194,-54.50848
13.86500,-27.73200,-54.81331
13.96500,-27.93206,-55.12328
14.06500,-28.13194,-55.39666
14.16500,-28.33200,-55.68880
14.26500,-28.53188,-56.02423
14.36500,-28.73194,-56.34058
14.46500,-28.93191,-56.62334
14.56500,-29.13197,-56.93328
14.66500,-29.33194,-57.23289
14.76500,-29.53200,-57.56906
14.86500,-29.73197,-57.89746
14.96500,-29.93203,-58.17393
15.06500,-30.13200,-58.45470
15.16500,-30.33206,-58.76417
15.26500,-30.53213,-59.11471
15.36500,-30.73191,-59.47267
15.46500,-30.93197,-59.80578
15.56500,-31.13203,-60.11823
15.66500,-31.33209,-60.42397
15.76500,-31.53197,-60.74939
15.86500,-31.73203,-61.08510
15.96500,-31.93200,-61.40316
16.06500,-32.13197,-61.75787
16.16500,-32.33194,-62.09058
16.26500,-32.53191,-62.37681
16.36500,-32.73197,-62.72753
16.46500,-32.93203,-63.02652
16.56500,-33.13200,-63.38897
16.66500,-33.33197,-63.67671
16.76500,-33.53203,-63.98164
16.86500,-33.73200,-64.32880
16.96500,-33.93197,-64.68802
17.06500,-34.13203,-65.09833
17.16500,-34.33191,-65.44434
17.26500,-34.53197,-65.81219
17.36500,-34.73194,-66.13098
17.46500,-34.93200,-66.50203
17.56500,-35.13197,-66.60374
17.66500,-35.33203,-66.92094
17.76500,-35.53200,-67.28426
17.86500,-35.73197,-67.69297
17.96500,-35.93203,-68.07034
18.06500,-36.13209,-68.43029
18.16500,-36.33206,-68.85652
18.26500,-36.53203,-69.24754
18.36500,-36.73210,-69.61982
18.46500,-36.93206,-70.01212
18.56500,-37.13194,-70.49011
18.66500,-37.33191,-70.92120
18.76500,-37.53188,-71.31039
18.86500,-37.73175,-71.63054
18.96500,-37.93191,-72.06644
19.06500,-38.13206,-72.47089
19.16500,-38.33194,-72.83796
19.26500,-38.53191,-73.25247
19.36500,-38.73197,-73.66108
19.46500,-38.93194,-74.00967
19.56500,-39.13200,-74.45993
19.66500,-39.33207,-74.90560
19.76500,-39.53203,-75.26768
19.86500,-39.73209,-75.66429
19.96500,-39.93206,-76.08269
20.04500,-40.09200,-76.45003